# 测试.调试.异常

## 处理多个异常

```python
try:
    client_obj.get_url(url)
except (URLError, ValueError, SocketTimeout):
    client_obj.remove_url(url)
```
## except 语句是顺序检查的，第一个匹配的会执行

```python
>>> try:
...     f = open('missing')
... except OSError:
...     print ('It failed')
... except FileNotFoundError:
...     print ('File not found')
It failed
```

## 捕获所有异常
* 这个将会捕获除了 SystemExit 、 KeyboardInterrupt 和 GeneratorExit 之外的所有异常,如果你还想捕获这三个异常，将 Exception 改成 BaseException 即可。

```python
try:
   ...
except Exception as e:
   ...
   log('Reason:', e)
```
## 自定义异常
* 自定义异常类应该总是继承自内置的 Exception 类， 或者是继承自那些本身就是从 Exception 继承而来的类
* 不要继承BaseException
* 定义的新异常 __init__() 方法， 构造函数中调用Exception.__init__() 

```python
class CustomerError(Exception):
    def __init__(self, message, status):
        super(Exception, self).__init__(message, status)
        self.message = message
        self.status = status

if __name__ == '__main__':
    try:
        raise CustomerError('ERROR', -1)
    except CustomerError as e:
        print (e.status)
        print (e.args)
```

## 重新抛出被捕获的异常
* 在except中捕获,使用raise重新抛出即可

```python
def example():
    try:
        int('N/A')
    except ValueError:
        raise
```
